Workbook

Sheet KPI
A1: STORE
A2: Category | B2: ITEM | C2: TARGET | D2: CONTRIBUTION | E2: CARA PENILAIAN
A3: Sales Achievement | B3: Net Sales | C3: Tier 2 | D3: 0.4 | E3: Tercapai Tier 2
A4: Sales Achievement | B4: AVG Transactions | C4: 55000 | D4: 0.1 | E4: Net Sales AVG
A5: Sales Achievement | B5: Large Attach Rate | C5: 0.65 | D5: 0.05 | E5: Rasio Large 65% dari seluruh cup yang terjual
A6: Sales Achievement | B6: Oatmilk Attach Rate | C6: 0.05 | D6: 0.05 | E6: Rasio Oatmilk 5% dari seluruh minuman dengan modifier oatmilk
A7: Sales Achievement | B7: Snack Platter Attach Rate | C7: 0.1 | D7: 0.05 | E7: Rasio Snack Platter 10% dari seluruh snack yang terjual
A8: Sales Achievement | B8: Bundling Asik Attach Rate | C8: 0.05 | D8: 0.05 | E8: Rasio Bundling Asik 5% dari Transaksi selama periode
A9: Quality & Compliance | B9: Audit | C9: 0.9 | D9: 0.15 | E9: APD
A10: Quality & Compliance | B10: Mistery Shopper | C10: 1 | D10: 0.05 | E10: Mistery Shopper
A11: Quality & Compliance | B11: Complain | C11: 0.001 | D11: 0.1 | E11: Rasio komplain maksimal 0.10%
A15: STORE MANAGER
A16: CATEGORY | B16: ITEM | C16: TARGET | D16: CONTRIBUTION | E16: CARA PENILAIAN
A17: Sales Execution & Control | B17: Daily Target Briefing & Shift Brief | C17: 1 | D17: 0.05 | E17: Video ke DM
A18: Sales Execution & Control | B18: Monitoring AVG Transaction & Attach Rate | C18: 1 | D18: 0.05 | E18: Buat Laporan Setiap Hari ke DM
A19: Sales Execution & Control | B19: Achievement Sales KPI Store | C19: 1 | D19: 0.4 | E19: Target Sales Daily Tercapai
A20: Cost & Inventory Control | B20: HPP Control | C20: 0.47 | D20: 0.05 | E20: HPP Finance
A21: Cost & Inventory Control | B21: Waste & Spoil Monitoring | C21: 1 | D21: 0.025 | E21: LOG Lengkap
A22: Cost & Inventory Control | B22: Stock Accuracy & FIFO | C22: 1 | D22: 0.025 | E22: Audit DM Mingguan
A23: Cost & Inventory Control | B23: Opex | C23: 0.03 | D23: 0.025 | E23: Deviasi vs Budget
A24: Team Management & Coaching | B24: Coaching LOG Staff | C24: 0.5 | D24: 0.05 | E24: Coaching 1-1
A25: Team Management & Coaching | B25: Training Execution | C25: 1 | D25: 0.05 | E25: Training by Modul
A26: Team Management & Coaching | B26: Staff Discipline & Attendance | C26: 1 | D26: 0.025 | E26: Sesuai SOP HR
A27: Quality & Compliance | B27: Audit Score | C27: 0.9 | D27: 0.1 | E27: Sesuai SOP Audit
A28: Quality & Compliance | B28: SOP & Cleanliness | C28: 1 | D28: 0.05 | E28: Audit DM Mingguan
A29: Quality & Compliance | B29: Retention | C29: 0.05 | D29: 0.05 | E29: Staff yang resign
A30: Customer Handling | B30: Complain Handling SLA | C30: 3x24 Jam | D30: 0.05 | E30: Admin CS
A33: DISTRICT MANAGER
A34: CATEGORY | B34: ITEM | C34: TARGET | D34: CONTRIBUTION | E34: CARA PENILAIAN
A35: Store Performance Governance | B35: % Store Achieve KPI Sales | C35: 1 | D35: 0.4 | E35: KPI Store
A36: Store Performance Governance | B36: AVG Sales & Attach Rate District | C36: 1 | D36: 0.1 | E36: vs Target
A37: Head Store Effectiveness | B37: % Head Store KPI Achievement | C37: 1 | D37: 0.1 | E37: KPI Head Store
A38: Head Store Effectiveness | B38: Head Store Coaching | C38: 1 | D38: 0.05 | E38: Coaching LOG
A39: Head Store Effectiveness | B39: Head Store Discipline & Compliance | C39: 1 | D39: 0.05 | E39: Major Issue
A40: Operational Control & Risk | B40: AVG HPP District | C40: 0.475 | D40: 0.05 | E40: HPP Finance
A41: Operational Control & Risk | B41: Audit Pass Rate | C41: 0.9 | D41: 0.05 | E41: Audit
A42: Operational Control & Risk | B42: Complaint Closure SLA | C42: 3x24Jam | D42: 0.05 | E42: <SLA
A43: Execution & Discipline | B43: Store Visit Coverage | C43: 1 | D43: 0.1 | E43: Visit Log
A44: Execution & Discipline | B44: Action Plan Closure | C44: 1 | D44: 0.05 | E44: Head Store Follow UP
A47: AREA MANAGER
...

Sheet Jan
B1: Store | C1: Net Sales | D1: AVG | E1: Large | F1: Oatside | G1: Snack Platter | H1: B. Asik | I1: Audit | J1: M. Shopper | K1: Complain | L1: Total | N1: Orang | O1: Score
A2: Nadine | B2: Kranggan | C2: {=iferror(LET( kode, B2, actual, XLOOKUP(kode, Sales!A:A, Sales!C:C), target, XLOOKUP(kode, Sales!A:A, Sales!B:B), ratio, actual/target, skor, IFS( ratio>1, 5, ratio>=0.975, 4, ratio>=0.95, 3, ratio>=0.9, 2, TRUE, 1 ), skor ),0)} -> 4 | D2: {=iferror(LET( kode, B2, actual, XLOOKUP(kode, AVG!A:A, AVG!C:C), target, XLOOKUP(kode, AVG!A:A, AVG!B:B), ratio, actual/target, skor, IFS( ratio>1, 5, ratio>=0.975, 4, ratio>=0.95, 3, ratio>=0.9, 2, TRUE, 1 ), skor ),0)} -> 5 | E2: {=iferror(LET( kode, B2, large, XLOOKUP(kode, Large!A:A, Large!C:C), small, XLOOKUP(kode, Large!A:A, Large!B:B), ratio, large/(large+small), skor, IFS( ratio<0.45, 1, ratio<=0.5, 2, ratio<=0.55, 3, ratio<=0.6, 4, TRUE, 5 ), skor ),0)} -> 4 | F2: {=iferror(LET( kode, B2, oatmilk, XLOOKUP(kode, Oatside!A:A, Oatside!C:C), drink, XLOOKUP(kode, Oatside!A:A, Oatside!B:B), ratio, oatmilk/drink, skor, IFS( ratio>5%, 5, ratio>=4%, 4, ratio>=3%, 3, ratio>=2%, 2, TRUE, 1 ), skor ),0)} -> 5 | G2: {=iferror(LET( kode, B2, actual, XLOOKUP(kode, 'Snack Platter'!A:A, 'Snack Platter'!C:C), target, XLOOKUP(kode, 'Snack Platter'!A:A, 'Snack Platter'!B:B), ratio, actual/target, skor, IFS( ratio>10%, 5, ratio>=7.5%, 4, ratio>=5%, 3, ratio>=2.5%, 2, TRUE, 1 ), skor ),0)} -> 3 | H2: {=iferror(LET( kode, B2, actual, XLOOKUP(kode, 'Bundling Asik'!A:A, 'Bundling Asik'!C:C), target, XLOOKUP(kode, 'Bundling Asik'!A:A, 'Bundling Asik'!B:B), ratio, actual/target, skor, IFS( ratio>5%, 5, ratio>=4%, 4, ratio>=3%, 3, ratio>=2%, 2, TRUE, 1 ), skor ),0)} -> 5 | I2: {=iferror(LET( kode, B2, ratio, XLOOKUP(kode, Audit!A:A, Audit!B:B), skor, IFS( ratio>90, 5, ratio>=85, 4, ratio>=80, 3, ratio>=75, 2, TRUE, 1 ), skor ),0)} -> 5 | J2: {=iferror(LET( kode, B2, ratio, XLOOKUP(kode, 'Mistery Shopper'!A:A, 'Mistery Shopper'!B:B), skor, IFS( ratio>90%, 5, ratio>=85%, 4, ratio>=80%, 3, ratio>=75%, 2, TRUE, 1 ), skor ),0)} -> 5 | K2: {=iferror(LET( kode, B2, actual, XLOOKUP(kode, Complain!A:A, Complain!C:C), target, XLOOKUP(kode, Complain!A:A, Complain!B:B), ratio, actual/target, skor, IFS( ratio>=0.16%, 1, ratio>=0.15%, 2, ratio>=0.125%, 3, ratio>=0.1%, 4, TRUE, 5 ), skor ),0)} -> 5 | L2: =LET( nilai, C2:K2, bobot, {0.4,0.1,0.05,0.05,0.05,0.05,0.15,0.05,0.1}, SUMPRODUCT(nilai,bobot) )/5 -> 0.89 | N2: Risti | O2: =averageif(A:A,N2,L:L) -> 0.688
A3: Nadine | B3: Kota Wisata | C3: {=iferror(LET( kode, B3, actual, XLOOKUP(kode, Sales!A:A, Sales!C:C), target, XLOOKUP(kode, Sales!A:A, Sales!B:B), ratio, actual/target, skor, IFS( ratio>1, 5, ratio>=0.975, 4, ratio>=0.95, 3, ratio>=0.9, 2, TRUE, 1 ), skor ),0)} -> 5 | D3: {=iferror(LET( kode, B3, actual, XLOOKUP(kode, AVG!A:A, AVG!C:C), target, XLOOKUP(kode, AVG!A:A, AVG!B:B), ratio, actual/target, skor, IFS( ratio>1, 5, ratio>=0.975, 4, ratio>=0.95, 3, ratio>=0.9, 2, TRUE, 1 ), skor ),0)} -> 5 | E3: {=iferror(LET( kode, B3, large, XLOOKUP(kode, Large!A:A, Large!C:C), small, XLOOKUP(kode, Large!A:A, Large!B:B), ratio, large/(large+small), skor, IFS( ratio<0.45, 1, ratio<=0.5, 2, ratio<=0.55, 3, ratio<=0.6, 4, TRUE, 5 ), skor ),0)} -> 5 | F3: {=iferror(LET( kode, B3, oatmilk, XLOOKUP(kode, Oatside!A:A, Oatside!C:C), drink, XLOOKUP(kode, Oatside!A:A, Oatside!B:B), ratio, oatmilk/drink, skor, IFS( ratio>5%, 5, ratio>=4%, 4, ratio>=3%, 3, ratio>=2%, 2, TRUE, 1 ), skor ),0)} -> 5 | G3: {=iferror(LET( kode, B3, actual, XLOOKUP(kode, 'Snack Platter'!A:A, 'Snack Platter'!C:C), target, XLOOKUP(kode, 'Snack Platter'!A:A, 'Snack Platter'!B:B), ratio, actual/target, skor, IFS( ratio>10%, 5, ratio>=7.5%, 4, ratio>=5%, 3, ratio>=2.5%, 2, TRUE, 1 ), skor ),0)} -> 4 | H3: {=iferror(LET( kode, B3, actual, XLOOKUP(kode, 'Bundling Asik'!A:A, 'Bundling Asik'!C:C), target, XLOOKUP(kode, 'Bundling Asik'!A:A, 'Bundling Asik'!B:B), ratio, actual/target, skor, IFS( ratio>5%, 5, ratio>=4%, 4, ratio>=3%, 3, ratio>=2%, 2, TRUE, 1 ), skor ),0)} -> 4 | I3: {=iferror(LET( kode, B3, ratio, XLOOKUP(kode, Audit!A:A, Audit!B:B), skor, IFS( ratio>90, 5, ratio>=85, 4, ratio>=80, 3, ratio>=75, 2, TRUE, 1 ), skor ),0)} -> 4 | J3: {=iferror(LET( kode, B3, ratio, XLOOKUP(kode, 'Mistery Shopper'!A:A, 'Mistery Shopper'!B:B), skor, IFS( ratio>90%, 5, ratio>=85%, 4, ratio>=80%, 3, ratio>=75%, 2, TRUE, 1 ), skor ),0)} -> 5 | K3: {=iferror(LET( kode, B3, actual, XLOOKUP(kode, Complain!A:A, Complain!C:C), target, XLOOKUP(kode, Complain!A:A, Complain!B:B), ratio, actual/target, skor, IFS( ratio>=0.16%, 1, ratio>=0.15%, 2, ratio>=0.125%, 3, ratio>=0.1%, 4, TRUE, 5 ), skor ),0)} -> 1 | L3: =LET( nilai, C3:K3, bobot, {0.4,0.1,0.05,0.05,0.05,0.05,0.15,0.05,0.1}, SUMPRODUCT(nilai,bobot) )/5 -> 0.87 | N3: Nadine | O3: =averageif(A:A,N3,L:L) -> 0.682
A4: Risti | B4: Metro | C4: {=iferror(LET( kode, B4, actual, XLOOKUP(kode, Sales!A:A, Sales!C:C), target, XLOOKUP(kode, Sales!A:A, Sales!B:B), ratio, actual/target, skor, IFS( ratio>1, 5, ratio>=0.975, 4, ratio>=0.95, 3, ratio>=0.9, 2, TRUE, 1 ), skor ),0)} -> 5 | D4: {=iferror(LET( kode, B4, actual, XLOOKUP(kode, AVG!A:A, AVG!C:C), target, XLOOKUP(kode, AVG!A:A, AVG!B:B), ratio, actual/target, skor, IFS( ratio>1, 5, ratio>=0.975, 4, ratio>=0.95, 3, ratio>=0.9, 2, TRUE, 1 ), skor ),0)} -> 4 | E4: {=iferror(LET( kode, B4, large, XLOOKUP(kode, Large!A:A, Large!C:C), small, XLOOKUP(kode, Large!A:A, Large!B:B), ratio, large/(large+small), skor, IFS( ratio<0.45, 1, ratio<=0.5, 2, ratio<=0.55, 3, ratio<=0.6, 4, TRUE, 5 ), skor ),0)} -> 1 | F4: {=iferror(LET( kode, B4, oatmilk, XLOOKUP(kode, Oatside!A:A, Oatside!C:C), drink, XLOOKUP(kode, Oatside!A:A, Oatside!B:B), ratio, oatmilk/drink, skor, IFS( ratio>5%, 5, ratio>=4%, 4, ratio>=3%, 3, ratio>=2%, 2, TRUE, 1 ), skor ),0)} -> 5 | G4: {=iferror(LET( kode, B4, actual, XLOOKUP(kode, 'Snack Platter'!A:A, 'Snack Platter'!C:C), target, XLOOKUP(kode, 'Snack Platter'!A:A, 'Snack Platter'!B:B), ratio, actual/target, skor, IFS( ratio>10%, 5, ratio>=7.5%, 4, ratio>=5%, 3, ratio>=2.5%, 2, TRUE, 1 ), skor ),0)} -> 2 | H4: {=iferror(LET( kode, B4, actual, XLOOKUP(kode, 'Bundling Asik'!A:A, 'Bundling Asik'!C:C), target, XLOOKUP(kode, 'Bundling Asik'!A:A, 'Bundling Asik'!B:B), ratio, actual/target, skor, IFS( ratio>5%, 5, ratio>=4%, 4, ratio>=3%, 3, ratio>=2%, 2, TRUE, 1 ), skor ),0)} -> 2 | I4: {=iferror(LET( kode, B4, ratio, XLOOKUP(kode, Audit!A:A, Audit!B:B), skor, IFS( ratio>90, 5, ratio>=85, 4, ratio>=80, 3, ratio>=75, 2, TRUE, 1 ), skor ),0)} -> 4 | J4: {=iferror(LET( kode, B4, ratio, XLOOKUP(kode, 'Mistery Shopper'!A:A, 'Mistery Shopper'!B:B), skor, IFS( ratio>90%, 5, ratio>=85%, 4, ratio>=80%, 3, ratio>=75%, 2, TRUE, 1 ), skor ),0)} -> 5 | K4: {=iferror(LET( kode, B4, actual, XLOOKUP(kode, Complain!A:A, Complain!C:C), target, XLOOKUP(kode, Complain!A:A, Complain!B:B), ratio, actual/target, skor, IFS( ratio>=0.16%, 1, ratio>=0.15%, 2, ratio>=0.125%, 3, ratio>=0.1%, 4, TRUE, 5 ), skor ),0)} -> 5 | L4: =LET( nilai, C4:K4, bobot, {0.4,0.1,0.05,0.05,0.05,0.05,0.15,0.05,0.1}, SUMPRODUCT(nilai,bobot) )/5 -> 0.85 | N4: Sohib | O4: =averageif(A:A,N4,L:L) -> 0.625
A5: Risti | B5: Kiara Artha | C5: {=iferror(LET( kode, B5, actual, XLOOKUP(kode, Sales!A:A, Sales!C:C), target, XLOOKUP(kode, Sales!A:A, Sales!B:B), ratio, actual/target, skor, IFS( ratio>1, 5, ratio>=0.975, 4, ratio>=0.95, 3, ratio>=0.9, 2, TRUE, 1 ), skor ),0)} -> 5 | D5: {=iferror(LET( kode, B5, actual, XLOOKUP(kode, AVG!A:A, AVG!C:C), target, XLOOKUP(kode, AVG!A:A, AVG!B:B), ratio, actual/target, skor, IFS( ratio>1, 5, ratio>=0.975, 4, ratio>=0.95, 3, ratio>=0.9, 2, TRUE, 1 ), skor ),0)} -> 4 | E5: {=iferror(LET( kode, B5, large, XLOOKUP(kode, Large!A:A, Large!C:C), small, XLOOKUP(kode, Large!A:A, Large!B:B), ratio, large/(large+small), skor, IFS( ratio<0.45, 1, ratio<=0.5, 2, ratio<=0.55, 3, ratio<=0.6, 4, TRUE, 5 ), skor ),0)} -> 1 | F5: {=iferror(LET( kode, B5, oatmilk, XLOOKUP(kode, Oatside!A:A, Oatside!C:C), drink, XLOOKUP(kode, Oatside!A:A, Oatside!B:B), ratio, oatmilk/drink, skor, IFS( ratio>5%, 5, ratio>=4%, 4, ratio>=3%, 3, ratio>=2%, 2, TRUE, 1 ), skor ),0)} -> 5 | G5: {=iferror(LET( kode, B5, actual, XLOOKUP(kode, 'Snack Platter'!A:A, 'Snack Platter'!C:C), target, XLOOKUP(kode, 'Snack Platter'!A:A, 'Snack Platter'!B:B), ratio, actual/target, skor, IFS( ratio>10%, 5, ratio>=7.5%, 4, ratio>=5%, 3, ratio>=2.5%, 2, TRUE, 1 ), skor ),0)} -> 1 | H5: {=iferror(LET( kode, B5, actual, XLOOKUP(kode, 'Bundling Asik'!A:A, 'Bundling Asik'!C:C), target, XLOOKUP(kode, 'Bundling Asik'!A:A, 'Bundling Asik'!B:B), ratio, actual/target, skor, IFS( ratio>5%, 5, ratio>=4%, 4, ratio>=3%, 3, ratio>=2%, 2, TRUE, 1 ), skor ),0)} -> 2 | I5: {=iferror(LET( kode, B5, ratio, XLOOKUP(kode, Audit!A:A, Audit!B:B), skor, IFS( ratio>90, 5, ratio>=85, 4, ratio>=80, 3, ratio>=75, 2, TRUE, 1 ), skor ),0)} -> 4 | J5: {=iferror(LET( kode, B5, ratio, XLOOKUP(kode, 'Mistery Shopper'!A:A, 'Mistery Shopper'!B:B), skor, IFS( ratio>90%, 5, ratio>=85%, 4, ratio>=80%, 3, ratio>=75%, 2, TRUE, 1 ), skor ),0)} -> 5 | K5: {=iferror(LET( kode, B5, actual, XLOOKUP(kode, Complain!A:A, Complain!C:C), target, XLOOKUP(kode, Complain!A:A, Complain!B:B), ratio, actual/target, skor, IFS( ratio>=0.16%, 1, ratio>=0.15%, 2, ratio>=0.125%, 3, ratio>=0.1%, 4, TRUE, 5 ), skor ),0)} -> 5 | L5: =LET( nilai, C5:K5, bobot, {0.4,0.1,0.05,0.05,0.05,0.05,0.15,0.05,0.1}, SUMPRODUCT(nilai,bobot) )/5 -> 0.84 | N5: Bagas | O5: =averageif(A:A,N5,L:L) -> 0.5075
A6: Sohib | B6: Cimahi | C6: {=iferror(LET( kode, B6, actual, XLOOKUP(kode, Sales!A:A, Sales!C:C), target, XLOOKUP(kode, Sales!A:A, Sales!B:B), ratio, actual/target, skor, IFS( ratio>1, 5, ratio>=0.975, 4, ratio>=0.95, 3, ratio>=0.9, 2, TRUE, 1 ), skor ),0)} -> 4 | D6: {=iferror(LET( kode, B6, actual, XLOOKUP(kode, AVG!A:A, AVG!C:C), target, XLOOKUP(kode, AVG!A:A, AVG!B:B), ratio, actual/target, skor, IFS( ratio>1, 5, ratio>=0.975, 4, ratio>=0.95, 3, ratio>=0.9, 2, TRUE, 1 ), skor ),0)} -> 5 | E6: {=iferror(LET( kode, B6, large, XLOOKUP(kode, Large!A:A, Large!C:C), small, XLOOKUP(kode, Large!A:A, Large!B:B), ratio, large/(large+small), skor, IFS( ratio<0.45, 1, ratio<=0.5, 2, ratio<=0.55, 3, ratio<=0.6, 4, TRUE, 5 ), skor ),0)} -> 1 | F6: {=iferror(LET( kode, B6, oatmilk, XLOOKUP(kode, Oatside!A:A, Oatside!C:C), drink, XLOOKUP(kode, Oatside!A:A, Oatside!B:B), ratio, oatmilk/drink, skor, IFS( ratio>5%, 5, ratio>=4%, 4, ratio>=3%, 3, ratio>=2%, 2, TRUE, 1 ), skor ),0)} -> 5 | G6: {=iferror(LET( kode, B6, actual, XLOOKUP(kode, 'Snack Platter'!A:A, 'Snack Platter'!C:C), target, XLOOKUP(kode, 'Snack Platter'!A:A, 'Snack Platter'!B:B), ratio, actual/target, skor, IFS( ratio>10%, 5, ratio>=7.5%, 4, ratio>=5%, 3, ratio>=2.5%, 2, TRUE, 1 ), skor ),0)} -> 2 | H6: {=iferror(LET( kode, B6, actual, XLOOKUP(kode, 'Bundling Asik'!A:A, 'Bundling Asik'!C:C), target, XLOOKUP(kode, 'Bundling Asik'!A:A, 'Bundling Asik'!B:B), ratio, actual/target, skor, IFS( ratio>5%, 5, ratio>=4%, 4, ratio>=3%, 3, ratio>=2%, 2, TRUE, 1 ), skor ),0)} -> 1 | I6: {=iferror(LET( kode, B6, ratio, XLOOKUP(kode, Audit!A:A, Audit!B:B), skor, IFS( ratio>90, 5, ratio>=85, 4, ratio>=80, 3, ratio>=75, 2, TRUE, 1 ), skor ),0)} -> 3 | J6: {=iferror(LET( kode, B6, ratio, XLOOKUP(kode, 'Mistery Shopper'!A:A, 'Mistery Shopper'!B:B), skor, IFS( ratio>90%, 5, ratio>=85%, 4, ratio>=80%, 3, ratio>=75%, 2, TRUE, 1 ), skor ),0)} -> 5 | K6: {=iferror(LET( kode, B6, actual, XLOOKUP(kode, Complain!A:A, Complain!C:C), target, XLOOKUP(kode, Complain!A:A, Complain!B:B), ratio, actual/target, skor, IFS( ratio>=0.16%, 1, ratio>=0.15%, 2, ratio>=0.125%, 3, ratio>=0.1%, 4, TRUE, 5 ), skor ),0)} -> 5 | L6: =LET( nilai, C6:K6, bobot, {0.4,0.1,0.05,0.05,0.05,0.05,0.15,0.05,0.1}, SUMPRODUCT(nilai,bobot) )/5 -> 0.75 | N6: Ryan | O6: =averageif(A:A,N6,L:L) -> 0.455
A7: Risti | B7: Ujung Berung | C7: {=iferror(LET( kode, B7, actual, XLOOKUP(kode, Sales!A:A, Sales!C:C), target, XLOOKUP(kode, Sales!A:A, Sales!B:B), ratio, actual/target, skor, IFS( ratio>1, 5, ratio>=0.975, 4, ratio>=0.95, 3, ratio>=0.9, 2, TRUE, 1 ), skor ),0)} -> 3 | D7: {=iferror(LET( kode, B7, actual, XLOOKUP(kode, AVG!A:A, AVG!C:C), target, XLOOKUP(kode, AVG!A:A, AVG!B:B), ratio, actual/target, skor, IFS( ratio>1, 5, ratio>=0.975, 4, ratio>=0.95, 3, ratio>=0.9, 2, TRUE, 1 ), skor ),0)} -> 5 | E7: {=iferror(LET( kode, B7, large, XLOOKUP(kode, Large!A:A, Large!C:C), small, XLOOKUP(kode, Large!A:A, Large!B:B), ratio, large/(large+small), skor, IFS( ratio<0.45, 1, ratio<=0.5, 2, ratio<=0.55, 3, ratio<=0.6, 4, TRUE, 5 ), skor ),0)} -> 2 | F7: {=iferror(LET( kode, B7, oatmilk, XLOOKUP(kode, Oatside!A:A, Oatside!C:C), drink, XLOOKUP(kode, Oatside!A:A, Oatside!B:B), ratio, oatmilk/drink, skor, IFS( ratio>5%, 5, ratio>=4%, 4, ratio>=3%, 3, ratio>=2%, 2, TRUE, 1 ), skor ),0)} -> 5 | G7: {=iferror(LET( kode, B7, actual, XLOOKUP(kode, 'Snack Platter'!A:A, 'Snack Platter'!C:C), target, XLOOKUP(kode, 'Snack Platter'!A:A, 'Snack Platter'!B:B), ratio, actual/target, skor, IFS( ratio>10%, 5, ratio>=7.5%, 4, ratio>=5%, 3, ratio>=2.5%, 2, TRUE, 1 ), skor ),0)} -> 2 | H7: {=iferror(LET( kode, B7, actual, XLOOKUP(kode, 'Bundling Asik'!A:A, 'Bundling Asik'!C:C), target, XLOOKUP(kode, 'Bundling Asik'!A:A, 'Bundling Asik'!B:B), ratio, actual/target, skor, IFS( ratio>5%, 5, ratio>=4%, 4, ratio>=3%, 3, ratio>=2%, 2, TRUE, 1 ), skor ),0)} -> 2 | I7: {=iferror(LET( kode, B7, ratio, XLOOKUP(kode, Audit!A:A, Audit!B:B), skor, IFS( ratio>90, 5, ratio>=85, 4, ratio>=80, 3, ratio>=75, 2, TRUE, 1 ), skor ),0)} -> 4 | J7: {=iferror(LET( kode, B7, ratio, XLOOKUP(kode, 'Mistery Shopper'!A:A, 'Mistery Shopper'!B:B), skor, IFS( ratio>90%, 5, ratio>=85%, 4, ratio>=80%, 3, ratio>=75%, 2, TRUE, 1 ), skor ),0)} -> 5 | K7: {=iferror(LET( kode, B7, actual, XLOOKUP(kode, Complain!A:A, Complain!C:C), target, XLOOKUP(kode, Complain!A:A, Complain!B:B), ratio, actual/target, skor, IFS( ratio>=0.16%, 1, ratio>=0.15%, 2, ratio>=0.125%, 3, ratio>=0.1%, 4, TRUE, 5 ), skor ),0)} -> 3 | L7: =LET( nilai, C7:K7, bobot, {0.4,0.1,0.05,0.05,0.05,0.05,0.15,0.05,0.1}, SUMPRODUCT(nilai,bobot) )/5 -> 0.68 | N7: Ismail | O7: =averageif(A:A,N7,L:L) -> 0.325
A8: Sohib | B8: Peta | C8: {=iferror(LET( kode, B8, actual, XLOOKUP(kode, Sales!A:A, Sales!C:C), target, XLOOKUP(kode, Sales!A:A, Sales!B:B), ratio, actual/target, skor, IFS( ratio>1, 5, ratio>=0.975, 4, ratio>=0.95, 3, ratio>=0.9, 2, TRUE, 1 ), skor ),0)} -> 3 | D8: {=iferror(LET( kode, B8, actual, XLOOKUP(kode, AVG!A:A, AVG!C:C), target, XLOOKUP(kode, AVG!A:A, AVG!B:B), ratio, actual/target, skor, IFS( ratio>1, 5, ratio>=0.975, 4, ratio>=0.95, 3, ratio>=0.9, 2, TRUE, 1 ), skor ),0)} -> 4 | E8: {=iferror(LET( kode, B8, large, XLOOKUP(kode, Large!A:A, Large!C:C), small, XLOOKUP(kode, Large!A:A, Large!B:B), ratio, large/(large+small), skor, IFS( ratio<0.45, 1, ratio<=0.5, 2, ratio<=0.55, 3, ratio<=0.6, 4, TRUE, 5 ), skor ),0)} -> 1 | F8: {=iferror(LET( kode, B8, oatmilk, XLOOKUP(kode, Oatside!A:A, Oatside!C:C), drink, XLOOKUP(kode, Oatside!A:A, Oatside!B:B), ratio, oatmilk/drink, skor, IFS( ratio>5%, 5, ratio>=4%, 4, ratio>=3%, 3, ratio>=2%, 2, TRUE, 1 ), skor ),0)} -> 5 | G8: {=iferror(LET( kode, B8, actual, XLOOKUP(kode, 'Snack Platter'!A:A, 'Snack Platter'!C:C), target, XLOOKUP(kode, 'Snack Platter'!A:A, 'Snack Platter'!B:B), ratio, actual/target, skor, IFS( ratio>10%, 5, ratio>=7.5%, 4, ratio>=5%, 3, ratio>=2.5%, 2, TRUE, 1 ), skor ),0)} -> 2 | H8: {=iferror(LET( kode, B8, actual, XLOOKUP(kode, 'Bundling Asik'!A:A, 'Bundling Asik'!C:C), target, XLOOKUP(kode, 'Bundling Asik'!A:A, 'Bundling Asik'!B:B), ratio, actual/target, skor, IFS( ratio>5%, 5, ratio>=4%, 4, ratio>=3%, 3, ratio>=2%, 2, TRUE, 1 ), skor ),0)} -> 1 | I8: {=iferror(LET( kode, B8, ratio, XLOOKUP(kode, Audit!A:A, Audit!B:B), skor, IFS( ratio>90, 5, ratio>=85, 4, ratio>=80, 3, ratio>=75, 2, TRUE, 1 ), skor ),0)} -> 4 | J8: {=iferror(LET( kode, B8, ratio, XLOOKUP(kode, 'Mistery Shopper'!A:A, 'Mistery Shopper'!B:B), skor, IFS( ratio>90%, 5, ratio>=85%, 4, ratio>=80%, 3, ratio>=75%, 2, TRUE, 1 ), skor ),0)} -> 5 | K8: {=iferror(LET( kode, B8, actual, XLOOKUP(kode, Complain!A:A, Complain!C:C), target, XLOOKUP(kode, Complain!A:A, Complain!B:B), ratio, actual/target, skor, IFS( ratio>=0.16%, 1, ratio>=0.15%, 2, ratio>=0.125%, 3, ratio>=0.1%, 4, TRUE, 5 ), skor ),0)} -> 5 | L8: =LET( nilai, C8:K8, bobot, {0.4,0.1,0.05,0.05,0.05,0.05,0.15,0.05,0.1}, SUMPRODUCT(nilai,bobot) )/5 -> 0.68
A9: Bagas | B9: Kalimalang | C9: {=iferror(LET( kode, B9, actual, XLOOKUP(kode, Sales!A:A, Sales!C:C), target, XLOOKUP(kode, Sales!A:A, Sales!B:B), ratio, actual/target, skor, IFS( ratio>1, 5, ratio>=0.975, 4, ratio>=0.95, 3, ratio>=0.9, 2, TRUE, 1 ), skor ),0)} -> 4 | D9: {=iferror(LET( kode, B9, actual, XLOOKUP(kode, AVG!A:A, AVG!C:C), target, XLOOKUP(kode, AVG!A:A, AVG!B:B), ratio, actual/target, skor, IFS( ratio>1, 5, ratio>=0.975, 4, ratio>=0.95, 3, ratio>=0.9, 2, TRUE, 1 ), skor ),0)} -> 5 | E9: {=iferror(LET( kode, B9, large, XLOOKUP(kode, Large!A:A, Large!C:C), small, XLOOKUP(kode, Large!A:A, Large!B:B), ratio, large/(large+small), skor, IFS( ratio<0.45, 1, ratio<=0.5, 2, ratio<=0.55, 3, ratio<=0.6, 4, TRUE, 5 ), skor ),0)} -> 1 | F9: {=iferror(LET( kode, B9, oatmilk, XLOOKUP(kode, Oatside!A:A, Oatside!C:C), drink, XLOOKUP(kode, Oatside!A:A, Oatside!B:B), ratio, oatmilk/drink, skor, IFS( ratio>5%, 5, ratio>=4%, 4, ratio>=3%, 3, ratio>=2%, 2, TRUE, 1 ), skor ),0)} -> 1 | G9: {=iferror(LET( kode, B9, actual, XLOOKUP(kode, 'Snack Platter'!A:A, 'Snack Platter'!C:C), target, XLOOKUP(kode, 'Snack Platter'!A:A, 'Snack Platter'!B:B), ratio, actual/target, skor, IFS( ratio>10%, 5, ratio>=7.5%, 4, ratio>=5%, 3, ratio>=2.5%, 2, TRUE, 1 ), skor ),0)} -> 1 | H9: {=iferror(LET( kode, B9, actual, XLOOKUP(kode, 'Bundling Asik'!A:A, 'Bundling Asik'!C:C), target, XLOOKUP(kode, 'Bundling Asik'!A:A, 'Bundling Asik'!B:B), ratio, actual/target, skor, IFS( ratio>5%, 5, ratio>=4%, 4, ratio>=3%, 3, ratio>=2%, 2, TRUE, 1 ), skor ),0)} -> 1 | I9: {=iferror(LET( kode, B9, ratio, XLOOKUP(kode, Audit!A:A, Audit!B:B), skor, IFS( ratio>90, 5, ratio>=85, 4, ratio>=80, 3, ratio>=75, 2, TRUE, 1 ), skor ),0)} -> 3 | J9: {=iferror(LET( kode, B9, ratio, XLOOKUP(kode, 'Mistery Shopper'!A:A, 'Mistery Shopper'!B:B), skor, IFS( ratio>90%, 5, ratio>=85%, 4, ratio>=80%, 3, ratio>=75%, 2, TRUE, 1 ), skor ),0)} -> 5 | K9: {=iferror(LET( kode, B9, actual, XLOOKUP(kode, Complain!A:A, Complain!C:C), target, XLOOKUP(kode, Complain!A:A, Complain!B:B), ratio, actual/target, skor, IFS( ratio>=0.16%, 1, ratio>=0.15%, 2, ratio>=0.125%, 3, ratio>=0.1%, 4, TRUE, 5 ), skor ),0)} -> 4 | L9: =LET( nilai, C9:K9, bobot, {0.4,0.1,0.05,0.05,0.05,0.05,0.15,0.05,0.1}, SUMPRODUCT(nilai,bobot) )/5 -> 0.68
A10: Ryan | B10: Ciledug | C10: {=iferror(LET( kode, B10, actual, XLOOKUP(kode, Sales!A:A, Sales!C:C), target, XLOOKUP(kode, Sales!A:A, Sales!B:B), ratio, actual/target, skor, IFS( ratio>1, 5, ratio>=0.975, 4, ratio>=0.95, 3, ratio>=0.9, 2, TRUE, 1 ), skor ),0)} -> 4 | D10: {=iferror(LET( kode, B10, actual, XLOOKUP(kode, AVG!A:A, AVG!C:C), target, XLOOKUP(kode, AVG!A:A, AVG!B:B), ratio, actual/target, skor, IFS( ratio>1, 5, ratio>=0.975, 4, ratio>=0.95, 3, ratio>=0.9, 2, TRUE, 1 ), skor ),0)} -> 5 | E10: {=iferror(LET( kode, B10, large, XLOOKUP(kode, Large!A:A, Large!C:C), small, XLOOKUP(kode, Large!A:A, Large!B:B), ratio, large/(large+small), skor, IFS( ratio<0.45, 1, ratio<=0.5, 2, ratio<=0.55, 3, ratio<=0.6, 4, TRUE, 5 ), skor ),0)} -> 1 | F10: {=iferror(LET( kode, B10, oatmilk, XLOOKUP(kode, Oatside!A:A, Oatside!C:C), drink, XLOOKUP(kode, Oatside!A:A, Oatside!B:B), ratio, oatmilk/drink, skor, IFS( ratio>5%, 5, ratio>=4%, 4, ratio>=3%, 3, ratio>=2%, 2, TRUE, 1 ), skor ),0)} -> 1 | G10: {=iferror(LET( kode, B10, actual, XLOOKUP(kode, 'Snack Platter'!A:A, 'Snack Platter'!C:C), target, XLOOKUP(kode, 'Snack Platter'!A:A, 'Snack Platter'!B:B), ratio, actual/target, skor, IFS( ratio>10%, 5, ratio>=7.5%, 4, ratio>=5%, 3, ratio>=2.5%, 2, TRUE, 1 ), skor ),0)} -> 1 | H10: {=iferror(LET( kode, B10, actual, XLOOKUP(kode, 'Bundling Asik'!A:A, 'Bundling Asik'!C:C), target, XLOOKUP(kode, 'Bundling Asik'!A:A, 'Bundling Asik'!B:B), ratio, actual/target, skor, IFS( ratio>5%, 5, ratio>=4%, 4, ratio>=3%, 3, ratio>=2%, 2, TRUE, 1 ), skor ),0)} -> 1 | I10: {=iferror(LET( kode, B10, ratio, XLOOKUP(kode, Audit!A:A, Audit!B:B), skor, IFS( ratio>90, 5, ratio>=85, 4, ratio>=80, 3, ratio>=75, 2, TRUE, 1 ), skor ),0)} -> 2 | J10: {=iferror(LET( kode, B10, ratio, XLOOKUP(kode, 'Mistery Shopper'!A:A, 'Mistery Shopper'!B:B), skor, IFS( ratio>90%, 5, ratio>=85%, 4, ratio>=80%, 3, ratio>=75%, 2, TRUE, 1 ), skor ),0)} -> 5 | K10: {=iferror(LET( kode, B10, actual, XLOOKUP(kode, Complain!A:A, Complain!C:C), target, XLOOKUP(kode, Complain!A:A, Complain!B:B), ratio, actual/target, skor, IFS( ratio>=0.16%, 1, ratio>=0.15%, 2, ratio>=0.125%, 3, ratio>=0.1%, 4, TRUE, 5 ), skor ),0)} -> 5 | L10: =LET( nilai, C10:K10, bobot, {0.4,0.1,0.05,0.05,0.05,0.05,0.15,0.05,0.1}, SUMPRODUCT(nilai,bobot) )/5 -> 0.67
A11: Sohib | B11: Melong | C11: {=iferror(LET( kode, B11, actual, XLOOKUP(kode, Sales!A:A, Sales!C:C), target, XLOOKUP(kode, Sales!A:A, Sales!B:B), ratio, actual/target, skor, IFS( ratio>1, 5, ratio>=0.975, 4, ratio>=0.95, 3, ratio>=0.9, 2, TRUE, 1 ), skor ),0)} -> 4 | D11: {=iferror(LET( kode, B11, actual, XLOOKUP(kode, AVG!A:A, AVG!C:C), target, XLOOKUP(kode, AVG!A:A, AVG!B:B), ratio, actual/target, skor, IFS( ratio>1, 5, ratio>=0.975, 4, ratio>=0.95, 3, ratio>=0.9, 2, TRUE, 1 ), skor ),0)} -> 1 | E11: {=iferror(LET( kode, B11, large, XLOOKUP(kode, Large!A:A, Large!C:C), small, XLOOKUP(kode, Large!A:A, Large!B:B), ratio, large/(large+small), skor, IFS( ratio<0.45, 1, ratio<=0.5, 2, ratio<=0.55, 3, ratio<=0.6, 4, TRUE, 5 ), skor ),0)} -> 1 | F11: {=iferror(LET( kode, B11, oatmilk, XLOOKUP(kode, Oatside!A:A, Oatside!C:C), drink, XLOOKUP(kode, Oatside!A:A, Oatside!B:B), ratio, oatmilk/drink, skor, IFS( ratio>5%, 5, ratio>=4%, 4, ratio>=3%, 3, ratio>=2%, 2, TRUE, 1 ), skor ),0)} -> 5 | G11: {=iferror(LET( kode, B11, actual, XLOOKUP(kode, 'Snack Platter'!A:A, 'Snack Platter'!C:C), target, XLOOKUP(kode, 'Snack Platter'!A:A, 'Snack Platter'!B:B), ratio, actual/target, skor, IFS( ratio>10%, 5, ratio>=7.5%, 4, ratio>=5%, 3, ratio>=2.5%, 2, TRUE, 1 ), skor ),0)} -> 1 | H11: {=iferror(LET( kode, B11, actual, XLOOKUP(kode, 'Bundling Asik'!A:A, 'Bundling Asik'!C:C), target, XLOOKUP(kode, 'Bundling Asik'!A:A, 'Bundling Asik'!B:B), ratio, actual/target, skor, IFS( ratio>5%, 5, ratio>=4%, 4, ratio>=3%, 3, ratio>=2%, 2, TRUE, 1 ), skor ),0)} -> 1 | I11: {=iferror(LET( kode, B11, ratio, XLOOKUP(kode, Audit!A:A, Audit!B:B), skor, IFS( ratio>90, 5, ratio>=85, 4, ratio>=80, 3, ratio>=75, 2, TRUE, 1 ), skor ),0)} -> 3 | J11: {=iferror(LET( kode, B11, ratio, XLOOKUP(kode, 'Mistery Shopper'!A:A, 'Mistery Shopper'!B:B), skor, IFS( ratio>90%, 5, ratio>=85%, 4, ratio>=80%, 3, ratio>=75%, 2, TRUE, 1 ), skor ),0)} -> 5 | K11: {=iferror(LET( kode, B11, actual, XLOOKUP(kode, Complain!A:A, Complain!C:C), target, XLOOKUP(kode, Complain!A:A, Complain!B:B), ratio, actual/target, skor, IFS( ratio>=0.16%, 1, ratio>=0.15%, 2, ratio>=0.125%, 3, ratio>=0.1%, 4, TRUE, 5 ), skor ),0)} -> 5 | L11: =LET( nilai, C11:K11, bobot, {0.4,0.1,0.05,0.05,0.05,0.05,0.15,0.05,0.1}, SUMPRODUCT(nilai,bobot) )/5 -> 0.66
A12: Bagas | B12: Lebak Bulus | C12: {=iferror(LET( kode, B12, actual, XLOOKUP(kode, Sales!A:A, Sales!C:C), target, XLOOKUP(kode, Sales!A:A, Sales!B:B), ratio, actual/target, skor, IFS( ratio>1, 5, ratio>=0.975, 4, ratio>=0.95, 3, ratio>=0.9, 2, TRUE, 1 ), skor ),0)} -> 3 | D12: {=iferror(LET( kode, B12, actual, XLOOKUP(kode, AVG!A:A, AVG!C:C), target, XLOOKUP(kode, AVG!A:A, AVG!B:B), ratio, actual/target, skor, IFS( ratio>1, 5, ratio>=0.975, 4, ratio>=0.95, 3, ratio>=0.9, 2, TRUE, 1 ), skor ),0)} -> 2 | E12: {=iferror(LET( kode, B12, large, XLOOKUP(kode, Large!A:A, Large!C:C), small, XLOOKUP(kode, Large!A:A, Large!B:B), ratio, large/(large+small), skor, IFS( ratio<0.45, 1, ratio<=0.5, 2, ratio<=0.55, 3, ratio<=0.6, 4, TRUE, 5 ), skor ),0)} -> 2 | F12: {=iferror(LET( kode, B12, oatmilk, XLOOKUP(kode, Oatside!A:A, Oatside!C:C), drink, XLOOKUP(kode, Oatside!A:A, Oatside!B:B), ratio, oatmilk/drink, skor, IFS( ratio>5%, 5, ratio>=4%, 4, ratio>=3%, 3, ratio>=2%, 2, TRUE, 1 ), skor ),0)} -> 5 | G12: {=iferror(LET( kode, B12, actual, XLOOKUP(kode, 'Snack Platter'!A:A, 'Snack Platter'!C:C), target, XLOOKUP(kode, 'Snack Platter'!A:A, 'Snack Platter'!B:B), ratio, actual/target, skor, IFS( ratio>10%, 5, ratio>=7.5%, 4, ratio>=5%, 3, ratio>=2.5%, 2, TRUE, 1 ), skor ),0)} -> 1 | H12: {=iferror(LET( kode, B12, actual, XLOOKUP(kode, 'Bundling Asik'!A:A, 'Bundling Asik'!C:C), target, XLOOKUP(kode, 'Bundling Asik'!A:A, 'Bundling Asik'!B:B), ratio, actual/target, skor, IFS( ratio>5%, 5, ratio>=4%, 4, ratio>=3%, 3, ratio>=2%, 2, TRUE, 1 ), skor ),0)} -> 1 | I12: {=iferror(LET( kode, B12, ratio, XLOOKUP(kode, Audit!A:A, Audit!B:B), skor, IFS( ratio>90, 5, ratio>=85, 4, ratio>=80, 3, ratio>=75, 2, TRUE, 1 ), skor ),0)} -> 3 | J12: {=iferror(LET( kode, B12, ratio, XLOOKUP(kode, 'Mistery Shopper'!A:A, 'Mistery Shopper'!B:B), skor, IFS( ratio>90%, 5, ratio>=85%, 4, ratio>=80%, 3, ratio>=75%, 2, TRUE, 1 ), skor ),0)} -> 5 | K12: {=iferror(LET( kode, B12, actual, XLOOKUP(kode, Complain!A:A, Complain!C:C), target, XLOOKUP(kode, Complain!A:A, Complain!B:B), ratio, actual/target, skor, IFS( ratio>=0.16%, 1, ratio>=0.15%, 2, ratio>=0.125%, 3, ratio>=0.1%, 4, TRUE, 5 ), skor ),0)} -> 5 | L12: =LET( nilai, C12:K12, bobot, {0.4,0.1,0.05,0.05,0.05,0.05,0.15,0.05,0.1}, SUMPRODUCT(nilai,bobot) )/5 -> 0.61
A13: Nadine | B13: Pekayon | C13: {=iferror(LET( kode, B13, actual, XLOOKUP(kode, Sales!A:A, Sales!C:C), target, XLOOKUP(kode, Sales!A:A, Sales!B:B), ratio, actual/target, skor, IFS( ratio>1, 5, ratio>=0.975, 4, ratio>=0.95, 3, ratio>=0.9, 2, TRUE, 1 ), skor ),0)} -> 2 | D13: {=iferror(LET( kode, B13, actual, XLOOKUP(kode, AVG!A:A, AVG!C:C), target, XLOOKUP(kode, AVG!A:A, AVG!B:B), ratio, actual/target, skor, IFS( ratio>1, 5, ratio>=0.975, 4, ratio>=0.95, 3, ratio>=0.9, 2, TRUE, 1 ), skor ),0)} -> 5 | E13: {=iferror(LET( kode, B13, large, XLOOKUP(kode, Large!A:A, Large!C:C), small, XLOOKUP(kode, Large!A:A, Large!B:B), ratio, large/(large+small), skor, IFS( ratio<0.45, 1, ratio<=0.5, 2, ratio<=0.55, 3, ratio<=0.6, 4, TRUE, 5 ), skor ),0)} -> 2 | F13: {=iferror(LET( kode, B13, oatmilk, XLOOKUP(kode, Oatside!A:A, Oatside!C:C), drink, XLOOKUP(kode, Oatside!A:A, Oatside!B:B), ratio, oatmilk/drink, skor, IFS( ratio>5%, 5, ratio>=4%, 4, ratio>=3%, 3, ratio>=2%, 2, TRUE, 1 ), skor ),0)} -> 1 | G13: {=iferror(LET( kode, B13, actual, XLOOKUP(kode, 'Snack Platter'!A:A, 'Snack Platter'!C:C), target, XLOOKUP(kode, 'Snack Platter'!A:A, 'Snack Platter'!B:B), ratio, actual/target, skor, IFS( ratio>10%, 5, ratio>=7.5%, 4, ratio>=5%, 3, ratio>=2.5%, 2, TRUE, 1 ), skor ),0)} -> 2 | H13: {=iferror(LET( kode, B13, actual, XLOOKUP(kode, 'Bundling Asik'!A:A, 'Bundling Asik'!C:C), target, XLOOKUP(kode, 'Bundling Asik'!A:A, 'Bundling Asik'!B:B), ratio, actual/target, skor, IFS( ratio>5%, 5, ratio>=4%, 4, ratio>=3%, 3, ratio>=2%, 2, TRUE, 1 ), skor ),0)} -> 2 | I13: {=iferror(LET( kode, B13, ratio, XLOOKUP(kode, Audit!A:A, Audit!B:B), skor, IFS( ratio>90, 5, ratio>=85, 4, ratio>=80, 3, ratio>=75, 2, TRUE, 1 ), skor ),0)} -> 3 | J13: {=iferror(LET( kode, B13, ratio, XLOOKUP(kode, 'Mistery Shopper'!A:A, 'Mistery Shopper'!B:B), skor, IFS( ratio>90%, 5, ratio>=85%, 4, ratio>=80%, 3, ratio>=75%, 2, TRUE, 1 ), skor ),0)} -> 5 | K13: {=iferror(LET( kode, B13, actual, XLOOKUP(kode, Complain!A:A, Complain!C:C), target, XLOOKUP(kode, Complain!A:A, Complain!B:B), ratio, actual/target, skor, IFS( ratio>=0.16%, 1, ratio>=0.15%, 2, ratio>=0.125%, 3, ratio>=0.1%, 4, TRUE, 5 ), skor ),0)} -> 5 | L13: =LET( nilai, C13:K13, bobot, {0.4,0.1,0.05,0.05,0.05,0.05,0.15,0.05,0.1}, SUMPRODUCT(nilai,bobot) )/5 -> 0.57
A14: Bagas | B14: Setu Cipayung | C14: {=iferror(LET( kode, B14, actual, XLOOKUP(kode, Sales!A:A, Sales!C:C), target, XLOOKUP(kode, Sales!A:A, Sales!B:B), ratio, actual/target, skor, IFS( ratio>1, 5, ratio>=0.975, 4, ratio>=0.95, 3, ratio>=0.9, 2, TRUE, 1 ), skor ),0)} -> 2 | D14: {=iferror(LET( kode, B14, actual, XLOOKUP(kode, AVG!A:A, AVG!C:C), target, XLOOKUP(kode, AVG!A:A, AVG!B:B), ratio, actual/target, skor, IFS( ratio>1, 5, ratio>=0.975, 4, ratio>=0.95, 3, ratio>=0.9, 2, TRUE, 1 ), skor ),0)} -> 4 | E14: {=iferror(LET( kode, B14, large, XLOOKUP(kode, Large!A:A, Large!C:C), small, XLOOKUP(kode, Large!A:A, Large!B:B), ratio, large/(large+small), skor, IFS( ratio<0.45, 1, ratio<=0.5, 2, ratio<=0.55, 3, ratio<=0.6, 4, TRUE, 5 ), skor ),0)} -> 1 | F14: {=iferror(LET( kode, B14, oatmilk, XLOOKUP(kode, Oatside!A:A, Oatside!C:C), drink, XLOOKUP(kode, Oatside!A:A, Oatside!B:B), ratio, oatmilk/drink, skor, IFS( ratio>5%, 5, ratio>=4%, 4, ratio>=3%, 3, ratio>=2%, 2, TRUE, 1 ), skor ),0)} -> 4 | G14: {=iferror(LET( kode, B14, actual, XLOOKUP(kode, 'Snack Platter'!A:A, 'Snack Platter'!C:C), target, XLOOKUP(kode, 'Snack Platter'!A:A, 'Snack Platter'!B:B), ratio, actual/target, skor, IFS( ratio>10%, 5, ratio>=7.5%, 4, ratio>=5%, 3, ratio>=2.5%, 2, TRUE, 1 ), skor ),0)} -> 2 | H14: {=iferror(LET( kode, B14, actual, XLOOKUP(kode, 'Bundling Asik'!A:A, 'Bundling Asik'!C:C), target, XLOOKUP(kode, 'Bundling Asik'!A:A, 'Bundling Asik'!B:B), ratio, actual/target, skor, IFS( ratio>5%, 5, ratio>=4%, 4, ratio>=3%, 3, ratio>=2%, 2, TRUE, 1 ), skor ),0)} -> 1 | I14: {=iferror(LET( kode, B14, ratio, XLOOKUP(kode, Audit!A:A, Audit!B:B), skor, IFS( ratio>90, 5, ratio>=85, 4, ratio>=80, 3, ratio>=75, 2, TRUE, 1 ), skor ),0)} -> 3 | J14: {=iferror(LET( kode, B14, ratio, XLOOKUP(kode, 'Mistery Shopper'!A:A, 'Mistery Shopper'!B:B), skor, IFS( ratio>90%, 5, ratio>=85%, 4, ratio>=80%, 3, ratio>=75%, 2, TRUE, 1 ), skor ),0)} -> 5 | K14: {=iferror(LET( kode, B14, actual, XLOOKUP(kode, Complain!A:A, Complain!C:C), target, XLOOKUP(kode, Complain!A:A, Complain!B:B), ratio, actual/target, skor, IFS( ratio>=0.16%, 1, ratio>=0.15%, 2, ratio>=0.125%, 3, ratio>=0.1%, 4, TRUE, 5 ), skor ),0)} -> 5 | L14: =LET( nilai, C14:K14, bobot, {0.4,0.1,0.05,0.05,0.05,0.05,0.15,0.05,0.1}, SUMPRODUCT(nilai,bobot) )/5 -> 0.56
A15: Nadine | B15: Lenteng Agung | C15: {=iferror(LET( kode, B15, actual, XLOOKUP(kode, Sales!A:A, Sales!C:C), target, XLOOKUP(kode, Sales!A:A, Sales!B:B), ratio, actual/target, skor, IFS( ratio>1, 5, ratio>=0.975, 4, ratio>=0.95, 3, ratio>=0.9, 2, TRUE, 1 ), skor ),0)} -> 2 | D15: {=iferror(LET( kode, B15, actual, XLOOKUP(kode, AVG!A:A, AVG!C:C), target, XLOOKUP(kode, AVG!A:A, AVG!B:B), ratio, actual/target, skor, IFS( ratio>1, 5, ratio>=0.975, 4, ratio>=0.95, 3, ratio>=0.9, 2, TRUE, 1 ), skor ),0)} -> 2 | E15: {=iferror(LET( kode, B15, large, XLOOKUP(kode, Large!A:A, Large!C:C), small, XLOOKUP(kode, Large!A:A, Large!B:B), ratio, large/(large+small), skor, IFS( ratio<0.45, 1, ratio<=0.5, 2, ratio<=0.55, 3, ratio<=0.6, 4, TRUE, 5 ), skor ),0)} -> 1 | F15: {=iferror(LET( kode, B15, oatmilk, XLOOKUP(kode, Oatside!A:A, Oatside!C:C), drink, XLOOKUP(kode, Oatside!A:A, Oatside!B:B), ratio, oatmilk/drink, skor, IFS( ratio>5%, 5, ratio>=4%, 4, ratio>=3%, 3, ratio>=2%, 2, TRUE, 1 ), skor ),0)} -> 5 | G15: {=iferror(LET( kode, B15, actual, XLOOKUP(kode, 'Snack Platter'!A:A, 'Snack Platter'!C:C), target, XLOOKUP(kode, 'Snack Platter'!A:A, 'Snack Platter'!B:B), ratio, actual/target, skor, IFS( ratio>10%, 5, ratio>=7.5%, 4, ratio>=5%, 3, ratio>=2.5%, 2, TRUE, 1 ), skor ),0)} -> 2 | H15: {=iferror(LET( kode, B15, actual, XLOOKUP(kode, 'Bundling Asik'!A:A, 'Bundling Asik'!C:C), target, XLOOKUP(kode, 'Bundling Asik'!A:A, 'Bundling Asik'!B:B), ratio, actual/target, skor, IFS( ratio>5%, 5, ratio>=4%, 4, ratio>=3%, 3, ratio>=2%, 2, TRUE, 1 ), skor ),0)} -> 1 | I15: {=iferror(LET( kode, B15, ratio, XLOOKUP(kode, Audit!A:A, Audit!B:B), skor, IFS( ratio>90, 5, ratio>=85, 4, ratio>=80, 3, ratio>=75, 2, TRUE, 1 ), skor ),0)} -> 4 | J15: {=iferror(LET( kode, B15, ratio, XLOOKUP(kode, 'Mistery Shopper'!A:A, 'Mistery Shopper'!B:B), skor, IFS( ratio>90%, 5, ratio>=85%, 4, ratio>=80%, 3, ratio>=75%, 2, TRUE, 1 ), skor ),0)} -> 5 | K15: {=iferror(LET( kode, B15, actual, XLOOKUP(kode, Complain!A:A, Complain!C:C), target, XLOOKUP(kode, Complain!A:A, Complain!B:B), ratio, actual/target, skor, IFS( ratio>=0.16%, 1, ratio>=0.15%, 2, ratio>=0.125%, 3, ratio>=0.1%, 4, TRUE, 5 ), skor ),0)} -> 5 | L15: =LET( nilai, C15:K15, bobot, {0.4,0.1,0.05,0.05,0.05,0.05,0.15,0.05,0.1}, SUMPRODUCT(nilai,bobot) )/5 -> 0.56
A16: Risti | B16: Jatinangor | C16: {=iferror(LET( kode, B16, actual, XLOOKUP(kode, Sales!A:A, Sales!C:C), target, XLOOKUP(kode, Sales!A:A, Sales!B:B), ratio, actual/target, skor, IFS( ratio>1, 5, ratio>=0.975, 4, ratio>=0.95, 3, ratio>=0.9, 2, TRUE, 1 ), skor ),0)} -> 1 | D16: {=iferror(LET( kode, B16, actual, XLOOKUP(kode, AVG!A:A, AVG!C:C), target, XLOOKUP(kode, AVG!A:A, AVG!B:B), ratio, actual/target, skor, IFS( ratio>1, 5, ratio>=0.975, 4, ratio>=0.95, 3, ratio>=0.9, 2, TRUE, 1 ), skor ),0)} -> 5 | E16: {=iferror(LET( kode, B16, large, XLOOKUP(kode, Large!A:A, Large!C:C), small, XLOOKUP(kode, Large!A:A, Large!B:B), ratio, large/(large+small), skor, IFS( ratio<0.45, 1, ratio<=0.5, 2, ratio<=0.55, 3, ratio<=0.6, 4, TRUE, 5 ), skor ),0)} -> 1 | F16: {=iferror(LET( kode, B16, oatmilk, XLOOKUP(kode, Oatside!A:A, Oatside!C:C), drink, XLOOKUP(kode, Oatside!A:A, Oatside!B:B), ratio, oatmilk/drink, skor, IFS( ratio>5%, 5, ratio>=4%, 4, ratio>=3%, 3, ratio>=2%, 2, TRUE, 1 ), skor ),0)} -> 5 | G16: {=iferror(LET( kode, B16, actual, XLOOKUP(kode, 'Snack Platter'!A:A, 'Snack Platter'!C:C), target, XLOOKUP(kode, 'Snack Platter'!A:A, 'Snack Platter'!B:B), ratio, actual/target, skor, IFS( ratio>10%, 5, ratio>=7.5%, 4, ratio>=5%, 3, ratio>=2.5%, 2, TRUE, 1 ), skor ),0)} -> 2 | H16: {=iferror(LET( kode, B16, actual, XLOOKUP(kode, 'Bundling Asik'!A:A, 'Bundling Asik'!C:C), target, XLOOKUP(kode, 'Bundling Asik'!A:A, 'Bundling Asik'!B:B), ratio, actual/target, skor, IFS( ratio>5%, 5, ratio>=4%, 4, ratio>=3%, 3, ratio>=2%, 2, TRUE, 1 ), skor ),0)} -> 2 | I16: {=iferror(LET( kode, B16, ratio, XLOOKUP(kode, Audit!A:A, Audit!B:B), skor, IFS( ratio>90, 5, ratio>=85, 4, ratio>=80, 3, ratio>=75, 2, TRUE, 1 ), skor ),0)} -> 4 | J16: {=iferror(LET( kode, B16, ratio, XLOOKUP(kode, 'Mistery Shopper'!A:A, 'Mistery Shopper'!B:B), skor, IFS( ratio>90%, 5, ratio>=85%, 4, ratio>=80%, 3, ratio>=75%, 2, TRUE, 1 ), skor ),0)} -> 5 | K16: {=iferror(LET( kode, B16, actual, XLOOKUP(kode, Complain!A:A, Complain!C:C), target, XLOOKUP(kode, Complain!A:A, Complain!B:B), ratio, actual/target, skor, IFS( ratio>=0.16%, 1, ratio>=0.15%, 2, ratio>=0.125%, 3, ratio>=0.1%, 4, TRUE, 5 ), skor ),0)} -> 5 | L16: =LET( nilai, C16:K16, bobot, {0.4,0.1,0.05,0.05,0.05,0.05,0.15,0.05,0.1}, SUMPRODUCT(nilai,bobot) )/5 -> 0.55
A17: Bagas | B17: Pengumben | C17: {=iferror(LET( kode, B17, actual, XLOOKUP(kode, Sales!A:A, Sales!C:C), target, XLOOKUP(kode, Sales!A:A, Sales!B:B), ratio, actual/target, skor, IFS( ratio>1, 5, ratio>=0.975, 4, ratio>=0.95, 3, ratio>=0.9, 2, TRUE, 1 ), skor ),0)} -> 1 | D17: {=iferror(LET( kode, B17, actual, XLOOKUP(kode, AVG!A:A, AVG!C:C), target, XLOOKUP(kode, AVG!A:A, AVG!B:B), ratio, actual/target, skor, IFS( ratio>1, 5, ratio>=0.975, 4, ratio>=0.95, 3, ratio>=0.9, 2, TRUE, 1 ), skor ),0)} -> 5 | E17: {=iferror(LET( kode, B17, large, XLOOKUP(kode, Large!A:A, Large!C:C), small, XLOOKUP(kode, Large!A:A, Large!B:B), ratio, large/(large+small), skor, IFS( ratio<0.45, 1, ratio<=0.5, 2, ratio<=0.55, 3, ratio<=0.6, 4, TRUE, 5 ), skor ),0)} -> 2 | F17: {=iferror(LET( kode, B17, oatmilk, XLOOKUP(kode, Oatside!A:A, Oatside!C:C), drink, XLOOKUP(kode, Oatside!A:A, Oatside!B:B), ratio, oatmilk/drink, skor, IFS( ratio>5%, 5, ratio>=4%, 4, ratio>=3%, 3, ratio>=2%, 2, TRUE, 1 ), skor ),0)} -> 5 | G17: {=iferror(LET( kode, B17, actual, XLOOKUP(kode, 'Snack Platter'!A:A, 'Snack Platter'!C:C), target, XLOOKUP(kode, 'Snack Platter'!A:A, 'Snack Platter'!B:B), ratio, actual/target, skor, IFS( ratio>10%, 5, ratio>=7.5%, 4, ratio>=5%, 3, ratio>=2.5%, 2, TRUE, 1 ), skor ),0)} -> 2 | H17: {=iferror(LET( kode, B17, actual, XLOOKUP(kode, 'Bundling Asik'!A:A, 'Bundling Asik'!C:C), target, XLOOKUP(kode, 'Bundling Asik'!A:A, 'Bundling Asik'!B:B), ratio, actual/target, skor, IFS( ratio>5%, 5, ratio>=4%, 4, ratio>=3%, 3, ratio>=2%, 2, TRUE, 1 ), skor ),0)} -> 1 | I17: {=iferror(LET( kode, B17, ratio, XLOOKUP(kode, Audit!A:A, Audit!B:B), skor, IFS( ratio>90, 5, ratio>=85, 4, ratio>=80, 3, ratio>=75, 2, TRUE, 1 ), skor ),0)} -> 4 | J17: {=iferror(LET( kode, B17, ratio, XLOOKUP(kode, 'Mistery Shopper'!A:A, 'Mistery Shopper'!B:B), skor, IFS( ratio>90%, 5, ratio>=85%, 4, ratio>=80%, 3, ratio>=75%, 2, TRUE, 1 ), skor ),0)} -> 5 | K17: {=iferror(LET( kode, B17, actual, XLOOKUP(kode, Complain!A:A, Complain!C:C), target, XLOOKUP(kode, Complain!A:A, Complain!B:B), ratio, actual/target, skor, IFS( ratio>=0.16%, 1, ratio>=0.15%, 2, ratio>=0.125%, 3, ratio>=0.1%, 4, TRUE, 5 ), skor ),0)} -> 4 | L17: =LET( nilai, C17:K17, bobot, {0.4,0.1,0.05,0.05,0.05,0.05,0.15,0.05,0.1}, SUMPRODUCT(nilai,bobot) )/5 -> 0.53
A18: Nadine | B18: Margonda | C18: {=iferror(LET( kode, B18, actual, XLOOKUP(kode, Sales!A:A, Sales!C:C), target, XLOOKUP(kode, Sales!A:A, Sales!B:B), ratio, actual/target, skor, IFS( ratio>1, 5, ratio>=0.975, 4, ratio>=0.95, 3, ratio>=0.9, 2, TRUE, 1 ), skor ),0)} -> 2 | D18: {=iferror(LET( kode, B18, actual, XLOOKUP(kode, AVG!A:A, AVG!C:C), target, XLOOKUP(kode, AVG!A:A, AVG!B:B), ratio, actual/target, skor, IFS( ratio>1, 5, ratio>=0.975, 4, ratio>=0.95, 3, ratio>=0.9, 2, TRUE, 1 ), skor ),0)} -> 2 | E18: {=iferror(LET( kode, B18, large, XLOOKUP(kode, Large!A:A, Large!C:C), small, XLOOKUP(kode, Large!A:A, Large!B:B), ratio, large/(large+small), skor, IFS( ratio<0.45, 1, ratio<=0.5, 2, ratio<=0.55, 3, ratio<=0.6, 4, TRUE, 5 ), skor ),0)} -> 1 | F18: {=iferror(LET( kode, B18, oatmilk, XLOOKUP(kode, Oatside!A:A, Oatside!C:C), drink, XLOOKUP(kode, Oatside!A:A, Oatside!B:B), ratio, oatmilk/drink, skor, IFS( ratio>5%, 5, ratio>=4%, 4, ratio>=3%, 3, ratio>=2%, 2, TRUE, 1 ), skor ),0)} -> 3 | G18: {=iferror(LET( kode, B18, actual, XLOOKUP(kode, 'Snack Platter'!A:A, 'Snack Platter'!C:C), target, XLOOKUP(kode, 'Snack Platter'!A:A, 'Snack Platter'!B:B), ratio, actual/target, skor, IFS( ratio>10%, 5, ratio>=7.5%, 4, ratio>=5%, 3, ratio>=2.5%, 2, TRUE, 1 ), skor ),0)} -> 2 | H18: {=iferror(LET( kode, B18, actual, XLOOKUP(kode, 'Bundling Asik'!A:A, 'Bundling Asik'!C:C), target, XLOOKUP(kode, 'Bundling Asik'!A:A, 'Bundling Asik'!B:B), ratio, actual/target, skor, IFS( ratio>5%, 5, ratio>=4%, 4, ratio>=3%, 3, ratio>=2%, 2, TRUE, 1 ), skor ),0)} -> 2 | I18: {=iferror(LET( kode, B18, ratio, XLOOKUP(kode, Audit!A:A, Audit!B:B), skor, IFS( ratio>90, 5, ratio>=85, 4, ratio>=80, 3, ratio>=75, 2, TRUE, 1 ), skor ),0)} -> 3 | J18: {=iferror(LET( kode, B18, ratio, XLOOKUP(kode, 'Mistery Shopper'!A:A, 'Mistery Shopper'!B:B), skor, IFS( ratio>90%, 5, ratio>=85%, 4, ratio>=80%, 3, ratio>=75%, 2, TRUE, 1 ), skor ),0)} -> 5 | K18: {=iferror(LET( kode, B18, actual, XLOOKUP(kode, Complain!A:A, Complain!C:C), target, XLOOKUP(kode, Complain!A:A, Complain!B:B), ratio, actual/target, skor, IFS( ratio>=0.16%, 1, ratio>=0.15%, 2, ratio>=0.125%, 3, ratio>=0.1%, 4, TRUE, 5 ), skor ),0)} -> 5 | L18: =LET( nilai, C18:K18, bobot, {0.4,0.1,0.05,0.05,0.05,0.05,0.15,0.05,0.1}, SUMPRODUCT(nilai,bobot) )/5 -> 0.52
A19: Risti | B19: Buah Batu | C19: {=iferror(LET( kode, B19, actual, XLOOKUP(kode, Sales!A:A, Sales!C:C), target, XLOOKUP(kode, Sales!A:A, Sales!B:B), ratio, actual/target, skor, IFS( ratio>1, 5, ratio>=0.975, 4, ratio>=0.95, 3, ratio>=0.9, 2, TRUE, 1 ), skor ),0)} -> 2 | D19: {=iferror(LET( kode, B19, actual, XLOOKUP(kode, AVG!A:A, AVG!C:C), target, XLOOKUP(kode, AVG!A:A, AVG!B:B), ratio, actual/target, skor, IFS( ratio>1, 5, ratio>=0.975, 4, ratio>=0.95, 3, ratio>=0.9, 2, TRUE, 1 ), skor ),0)} -> 5 | E19: {=iferror(LET( kode, B19, large, XLOOKUP(kode, Large!A:A, Large!C:C), small, XLOOKUP(kode, Large!A:A, Large!B:B), ratio, large/(large+small), skor, IFS( ratio<0.45, 1, ratio<=0.5, 2, ratio<=0.55, 3, ratio<=0.6, 4, TRUE, 5 ), skor ),0)} -> 1 | F19: {=iferror(LET( kode, B19, oatmilk, XLOOKUP(kode, Oatside!A:A, Oatside!C:C), drink, XLOOKUP(kode, Oatside!A:A, Oatside!B:B), ratio, oatmilk/drink, skor, IFS( ratio>5%, 5, ratio>=4%, 4, ratio>=3%, 3, ratio>=2%, 2, TRUE, 1 ), skor ),0)} -> 5 | G19: {=iferror(LET( kode, B19, actual, XLOOKUP(kode, 'Snack Platter'!A:A, 'Snack Platter'!C:C), target, XLOOKUP(kode, 'Snack Platter'!A:A, 'Snack Platter'!B:B), ratio, actual/target, skor, IFS( ratio>10%, 5, ratio>=7.5%, 4, ratio>=5%, 3, ratio>=2.5%, 2, TRUE, 1 ), skor ),0)} -> 1 | H19: {=iferror(LET( kode, B19, actual, XLOOKUP(kode, 'Bundling Asik'!A:A, 'Bundling Asik'!C:C), target, XLOOKUP(kode, 'Bundling Asik'!A:A, 'Bundling Asik'!B:B), ratio, actual/target, skor, IFS( ratio>5%, 5, ratio>=4%, 4, ratio>=3%, 3, ratio>=2%, 2, TRUE, 1 ), skor ),0)} -> 1 | I19: {=iferror(LET( kode, B19, ratio, XLOOKUP(kode, Audit!A:A, Audit!B:B), skor, IFS( ratio>90, 5, ratio>=85, 4, ratio>=80, 3, ratio>=75, 2, TRUE, 1 ), skor ),0)} -> 1 | J19: {=iferror(LET( kode, B19, ratio, XLOOKUP(kode, 'Mistery Shopper'!A:A, 'Mistery Shopper'!B:B), skor, IFS( ratio>90%, 5, ratio>=85%, 4, ratio>=80%, 3, ratio>=75%, 2, TRUE, 1 ), skor ),0)} -> 5 | K19: {=iferror(LET( kode, B19, actual, XLOOKUP(kode, Complain!A:A, Complain!C:C), target, XLOOKUP(kode, Complain!A:A, Complain!B:B), ratio, actual/target, skor, IFS( ratio>=0.16%, 1, ratio>=0.15%, 2, ratio>=0.125%, 3, ratio>=0.1%, 4, TRUE, 5 ), skor ),0)} -> 5 | L19: =LET( nilai, C19:K19, bobot, {0.4,0.1,0.05,0.05,0.05,0.05,0.15,0.05,0.1}, SUMPRODUCT(nilai,bobot) )/5 -> 0.52
... A31: Ismail | B31: Citraland | C31: {=iferror(LET( kode, B31, actual, XLOOKUP(kode, Sales!A:A, Sales!C:C), target, XLOOKUP(kode, Sales!A:A, Sales!B:B), ratio, actual/target, skor, IFS( ratio>1, 5, ratio>=0.975, 4, ratio>=0.95, 3, ratio>=0.9, 2, TRUE, 1 ), skor ),0)} -> 1 | D31: {=iferror(LET( kode, B31, actual, XLOOKUP(kode, AVG!A:A, AVG!C:C), target, XLOOKUP(kode, AVG!A:A, AVG!B:B), ratio, actual/target, skor, IFS( ratio>1, 5, ratio>=0.975, 4, ratio>=0.95, 3, ratio>=0.9, 2, TRUE, 1 ), skor ),0)} -> 1 | E31: {=iferror(LET( kode, B31, large, XLOOKUP(kode, Large!A:A, Large!C:C), small, XLOOKUP(kode, Large!A:A, Large!B:B), ratio, large/(large+small), skor, IFS( ratio<0.45, 1, ratio<=0.5, 2, ratio<=0.55, 3, ratio<=0.6, 4, TRUE, 5 ), skor ),0)} -> 1 | F31: {=iferror(LET( kode, B31, oatmilk, XLOOKUP(kode, Oatside!A:A, Oatside!C:C), drink, XLOOKUP(kode, Oatside!A:A, Oatside!B:B), ratio, oatmilk/drink, skor, IFS( ratio>5%, 5, ratio>=4%, 4, ratio>=3%, 3, ratio>=2%, 2, TRUE, 1 ), skor ),0)} -> 1 | G31: {=iferror(LET( kode, B31, actual, XLOOKUP(kode, 'Snack Platter'!A:A, 'Snack Platter'!C:C), target, XLOOKUP(kode, 'Snack Platter'!A:A, 'Snack Platter'!B:B), ratio, actual/target, skor, IFS( ratio>10%, 5, ratio>=7.5%, 4, ratio>=5%, 3, ratio>=2.5%, 2, TRUE, 1 ), skor ),0)} -> 1 | H31: {=iferror(LET( kode, B31, actual, XLOOKUP(kode, 'Bundling Asik'!A:A, 'Bundling Asik'!C:C), target, XLOOKUP(kode, 'Bundling Asik'!A:A, 'Bundling Asik'!B:B), ratio, actual/target, skor, IFS( ratio>5%, 5, ratio>=4%, 4, ratio>=3%, 3, ratio>=2%, 2, TRUE, 1 ), skor ),0)} -> 1 | I31: {=iferror(LET( kode, B31, ratio, XLOOKUP(kode, Audit!A:A, Audit!B:B), skor, IFS( ratio>90, 5, ratio>=85, 4, ratio>=80, 3, ratio>=75, 2, TRUE, 1 ), skor ),0)} -> 1 | J31: {=iferror(LET( kode, B31, ratio, XLOOKUP(kode, 'Mistery Shopper'!A:A, 'Mistery Shopper'!B:B), skor, IFS( ratio>90%, 5, ratio>=85%, 4, ratio>=80%, 3, ratio>=75%, 2, TRUE, 1 ), skor ),0)} -> 5 | K31: {=iferror(LET( kode, B31, actual, XLOOKUP(kode, Complain!A:A, Complain!C:C), target, XLOOKUP(kode, Complain!A:A, Complain!B:B), ratio, actual/target, skor, IFS( ratio>=0.16%, 1, ratio>=0.15%, 2, ratio>=0.125%, 3, ratio>=0.1%, 4, TRUE, 5 ), skor ),0)} -> 4 | L31: =LET( nilai, C31:K31, bobot, {0.4,0.1,0.05,0.05,0.05,0.05,0.15,0.05,0.1}, SUMPRODUCT(nilai,bobot) )/5 -> 0.3

Sheet Feb
B1: Store | C1: Net Sales | D1: AVG | E1: Large | F1: Oatside | G1: Add On Telur | H1: B. Asik | I1: Audit | J1: M. Shopper | K1: Complain | L1: Total | N1: Orang | O1: Score
A2: Risti | B2: Ujung Berung | C2: {=iferror(LET(kode, B2, actual, XLOOKUP(kode, Sales!A:A, Sales!E:E),target, XLOOKUP(kode, Sales!A:A, Sales!D:D),ratio, actual/target,skor, IFS(ratio>1, 5,ratio>=0.975, 4,ratio>=0.95, 3,ratio>=0.9, 2,TRUE, 1),skor),0)} -> 5 | D2: {=iferror(LET( kode, B2, actual, XLOOKUP(kode, AVG!A:A, AVG!E:E), target, XLOOKUP(kode, AVG!A:A, AVG!D:D), ratio, actual/target, skor, IFS( ratio>1, 5, ratio>=0.975, 4, ratio>=0.95, 3, ratio>=0.9, 2, TRUE, 1 ), skor ),0)} -> 5 | E2: {=iferror(LET( kode, B2, large, XLOOKUP(kode, Large!A:A, Large!E:E), small, XLOOKUP(kode, Large!A:A, Large!D:D), ratio, large/(large+small), skor, IFS( ratio<0.45, 1, ratio<=0.5, 2, ratio<=0.55, 3, ratio<=0.6, 4, TRUE, 5 ), skor ),0)} -> 2 | F2: {=iferror(LET( kode, B2, oatmilk, XLOOKUP(kode, Oatside!A:A, Oatside!E:E), drink, XLOOKUP(kode, Oatside!A:A, Oatside!D:D), ratio, oatmilk/drink, skor, IFS( ratio>5%, 5, ratio>=4%, 4, ratio>=3%, 3, ratio>=2%, 2, TRUE, 1 ), skor ),0)} -> 5 | G2: {=iferror(LET( kode, B2, actual, XLOOKUP(kode, 'Snack Platter'!A:A, 'Snack Platter'!E:E), target, XLOOKUP(kode, 'Snack Platter'!A:A, 'Snack Platter'!D:D), ratio, actual/target, skor, IFS( ratio>10%, 5, ratio>=7.5%, 4, ratio>=5%, 3, ratio>=2.5%, 2, TRUE, 1 ), skor ),0)} -> 5 | H2: {=iferror(LET( kode, B2, actual, XLOOKUP(kode, 'Bundling Asik'!A:A, 'Bundling Asik'!E:E), target, XLOOKUP(kode, 'Bundling Asik'!A:A, 'Bundling Asik'!D:D), ratio, actual/target, skor, IFS( ratio>5%, 5, ratio>=4%, 4, ratio>=3%, 3, ratio>=2%, 2, TRUE, 1 ), skor ),0)} -> 3 | I2: {=iferror(LET( kode, B2, ratio, XLOOKUP(kode, Audit!A:A, Audit!C:C), skor, IFS( ratio>90, 5, ratio>=85, 4, ratio>=80, 3, ratio>=75, 2, TRUE, 1 ), skor ),0)} -> 4 | J2: {=iferror(LET( kode, B2, ratio, XLOOKUP(kode, 'Mistery Shopper'!A:A, 'Mistery Shopper'!C:C), skor, IFS( ratio>90%, 5, ratio>=85%, 4, ratio>=80%, 3, ratio>=75%, 2, TRUE, 1 ), skor ),0)} -> 5 | K2: {=iferror(LET( kode, B2, actual, XLOOKUP(kode, Complain!A:A, Complain!E:E), target, XLOOKUP(kode, Complain!A:A, Complain!D:D), ratio, actual/target, skor, IFS( ratio>=0.16%, 1, ratio>=0.15%, 2, ratio>=0.125%, 3, ratio>=0.1%, 4, TRUE, 5 ), skor ),0)} -> 5 | L2: =LET( nilai, C2:K2, bobot, {0.4,0.1,0.05,0.05,0.05,0.05,0.15,0.05,0.1}, SUMPRODUCT(nilai,bobot) )/5 -> 0.92 | N2: Risti | O2: =averageif(A:A,N2,L:L) -> 0.696
A3: Sohib | B3: Cimahi | C3: {=iferror(LET(kode, B3, actual, XLOOKUP(kode, Sales!A:A, Sales!E:E),target, XLOOKUP(kode, Sales!A:A, Sales!D:D),ratio, actual/target,skor, IFS(ratio>1, 5,ratio>=0.975, 4,ratio>=0.95, 3,ratio>=0.9, 2,TRUE, 1),skor),0)} -> 5 | D3: {=iferror(LET( kode, B3, actual, XLOOKUP(kode, AVG!A:A, AVG!E:E), target, XLOOKUP(kode, AVG!A:A, AVG!D:D), ratio, actual/target, skor, IFS( ratio>1, 5, ratio>=0.975, 4, ratio>=0.95, 3, ratio>=0.9, 2, TRUE, 1 ), skor ),0)} -> 5 | E3: {=iferror(LET( kode, B3, large, XLOOKUP(kode, Large!A:A, Large!E:E), small, XLOOKUP(kode, Large!A:A, Large!D:D), ratio, large/(large+small), skor, IFS( ratio<0.45, 1, ratio<=0.5, 2, ratio<=0.55, 3, ratio<=0.6, 4, TRUE, 5 ), skor ),0)} -> 1 | F3: {=iferror(LET( kode, B3, oatmilk, XLOOKUP(kode, Oatside!A:A, Oatside!E:E), drink, XLOOKUP(kode, Oatside!A:A, Oatside!D:D), ratio, oatmilk/drink, skor, IFS( ratio>5%, 5, ratio>=4%, 4, ratio>=3%, 3, ratio>=2%, 2, TRUE, 1 ), skor ),0)} -> 5 | G3: {=iferror(LET( kode, B3, actual, XLOOKUP(kode, 'Snack Platter'!A:A, 'Snack Platter'!E:E), target, XLOOKUP(kode, 'Snack Platter'!A:A, 'Snack Platter'!D:D), ratio, actual/target, skor, IFS( ratio>10%, 5, ratio>=7.5%, 4, ratio>=5%, 3, ratio>=2.5%, 2, TRUE, 1 ), skor ),0)} -> 2 | H3: {=iferror(LET( kode, B3, actual, XLOOKUP(kode, 'Bundling Asik'!A:A, 'Bundling Asik'!E:E), target, XLOOKUP(kode, 'Bundling Asik'!A:A, 'Bundling Asik'!D:D), ratio, actual/target, skor, IFS( ratio>5%, 5, ratio>=4%, 4, ratio>=3%, 3, ratio>=2%, 2, TRUE, 1 ), skor ),0)} -> 2 | I3: {=iferror(LET( kode, B3, ratio, XLOOKUP(kode, Audit!A:A, Audit!C:C), skor, IFS( ratio>90, 5, ratio>=85, 4, ratio>=80, 3, ratio>=75, 2, TRUE, 1 ), skor ),0)} -> 4 | J3: {=iferror(LET( kode, B3, ratio, XLOOKUP(kode, 'Mistery Shopper'!A:A, 'Mistery Shopper'!C:C), skor, IFS( ratio>90%, 5, ratio>=85%, 4, ratio>=80%, 3, ratio>=75%, 2, TRUE, 1 ), skor ),0)} -> 5 | K3: {=iferror(LET( kode, B3, actual, XLOOKUP(kode, Complain!A:A, Complain!E:E), target, XLOOKUP(kode, Complain!A:A, Complain!D:D), ratio, actual/target, skor, IFS( ratio>=0.16%, 1, ratio>=0.15%, 2, ratio>=0.125%, 3, ratio>=0.1%, 4, TRUE, 5 ), skor ),0)} -> 5 | L3: =LET( nilai, C3:K3, bobot, {0.4,0.1,0.05,0.05,0.05,0.05,0.15,0.05,0.1}, SUMPRODUCT(nilai,bobot) )/5 -> 0.87 | N3: Nadine | O3: =averageif(A:A,N3,L:L) -> 0.676
A4: Nadine | B4: Lenteng Agung | C4: {=iferror(LET(kode, B4, actual, XLOOKUP(kode, Sales!A:A, Sales!E:E),target, XLOOKUP(kode, Sales!A:A, Sales!D:D),ratio, actual/target,skor, IFS(ratio>1, 5,ratio>=0.975, 4,ratio>=0.95, 3,ratio>=0.9, 2,TRUE, 1),skor),0)} -> 4 | D4: {=iferror(LET( kode, B4, actual, XLOOKUP(kode, AVG!A:A, AVG!E:E), target, XLOOKUP(kode, AVG!A:A, AVG!D:D), ratio, actual/target, skor, IFS( ratio>1, 5, ratio>=0.975, 4, ratio>=0.95, 3, ratio>=0.9, 2, TRUE, 1 ), skor ),0)} -> 3 | E4: {=iferror(LET( kode, B4, large, XLOOKUP(kode, Large!A:A, Large!E:E), small, XLOOKUP(kode, Large!A:A, Large!D:D), ratio, large/(large+small), skor, IFS( ratio<0.45, 1, ratio<=0.5, 2, ratio<=0.55, 3, ratio<=0.6, 4, TRUE, 5 ), skor ),0)} -> 5 | F4: {=iferror(LET( kode, B4, oatmilk, XLOOKUP(kode, Oatside!A:A, Oatside!E:E), drink, XLOOKUP(kode, Oatside!A:A, Oatside!D:D), ratio, oatmilk/drink, skor, IFS( ratio>5%, 5, ratio>=4%, 4, ratio>=3%, 3, ratio>=2%, 2, TRUE, 1 ), skor ),0)} -> 5 | G4: {=iferror(LET( kode, B4, actual, XLOOKUP(kode, 'Snack Platter'!A:A, 'Snack Platter'!E:E), target, XLOOKUP(kode, 'Snack Platter'!A:A, 'Snack Platter'!D:D), ratio, actual/target, skor, IFS( ratio>10%, 5, ratio>=7.5%, 4, ratio>=5%, 3, ratio>=2.5%, 2, TRUE, 1 ), skor ),0)} -> 5 | H4: {=iferror(LET( kode, B4, actual, XLOOKUP(kode, 'Bundling Asik'!A:A, 'Bundling Asik'!E:E), target, XLOOKUP(kode, 'Bundling Asik'!A:A, 'Bundling Asik'!D:D), ratio, actual/target, skor, IFS( ratio>5%, 5, ratio>=4%, 4, ratio>=3%, 3, ratio>=2%, 2, TRUE, 1 ), skor ),0)} -> 3 | I4: {=iferror(LET( kode, B4, ratio, XLOOKUP(kode, Audit!A:A, Audit!C:C), skor, IFS( ratio>90, 5, ratio>=85, 4, ratio>=80, 3, ratio>=75, 2, TRUE, 1 ), skor ),0)} -> 5 | J4: {=iferror(LET( kode, B4, ratio, XLOOKUP(kode, 'Mistery Shopper'!A:A, 'Mistery Shopper'!C:C), skor, IFS( ratio>90%, 5, ratio>=85%, 4, ratio>=80%, 3, ratio>=75%, 2, TRUE, 1 ), skor ),0)} -> 5 | K4: {=iferror(LET( kode, B4, actual, XLOOKUP(kode, Complain!A:A, Complain!E:E), target, XLOOKUP(kode, Complain!A:A, Complain!D:D), ratio, actual/target, skor, IFS( ratio>=0.16%, 1, ratio>=0.15%, 2, ratio>=0.125%, 3, ratio>=0.1%, 4, TRUE, 5 ), skor ),0)} -> 5 | L4: =LET( nilai, C4:K4, bobot, {0.4,0.1,0.05,0.05,0.05,0.05,0.15,0.05,0.1}, SUMPRODUCT(nilai,bobot) )/5 -> 0.86 | N4: Sohib | O4: =averageif(A:A,N4,L:L) -> 0.6875
A5: Risti | B5: Metro | C5: {=iferror(LET(kode, B5, actual, XLOOKUP(kode, Sales!A:A, Sales!E:E),target, XLOOKUP(kode, Sales!A:A, Sales!D:D),ratio, actual/target,skor, IFS(ratio>1, 5,ratio>=0.975, 4,ratio>=0.95, 3,ratio>=0.9, 2,TRUE, 1),skor),0)} -> 5 | D5: {=iferror(LET( kode, B5, actual, XLOOKUP(kode, AVG!A:A, AVG!E:E), target, XLOOKUP(kode, AVG!A:A, AVG!D:D), ratio, actual/target, skor, IFS( ratio>1, 5, ratio>=0.975, 4, ratio>=0.95, 3, ratio>=0.9, 2, TRUE, 1 ), skor ),0)} -> 2 | E5: {=iferror(LET( kode, B5, large, XLOOKUP(kode, Large!A:A, Large!E:E), small, XLOOKUP(kode, Large!A:A, Large!D:D), ratio, large/(large+small), skor, IFS( ratio<0.45, 1, ratio<=0.5, 2, ratio<=0.55, 3, ratio<=0.6, 4, TRUE, 5 ), skor ),0)} -> 1 | F5: {=iferror(LET( kode, B5, oatmilk, XLOOKUP(kode, Oatside!A:A, Oatside!E:E), drink, XLOOKUP(kode, Oatside!A:A, Oatside!D:D), ratio, oatmilk/drink, skor, IFS( ratio>5%, 5, ratio>=4%, 4, ratio>=3%, 3, ratio>=2%, 2, TRUE, 1 ), skor ),0)} -> 5 | G5: {=iferror(LET( kode, B5, actual, XLOOKUP(kode, 'Snack Platter'!A:A, 'Snack Platter'!E:E), target, XLOOKUP(kode, 'Snack Platter'!A:A, 'Snack Platter'!D:D), ratio, actual/target, skor, IFS( ratio>10%, 5, ratio>=7.5%, 4, ratio>=5%, 3, ratio>=2.5%, 2, TRUE, 1 ), skor ),0)} -> 2 | H5: {=iferror(LET( kode, B5, actual, XLOOKUP(kode, 'Bundling Asik'!A:A, 'Bundling Asik'!E:E), target, XLOOKUP(kode, 'Bundling Asik'!A:A, 'Bundling Asik'!D:D), ratio, actual/target, skor, IFS( ratio>5%, 5, ratio>=4%, 4, ratio>=3%, 3, ratio>=2%, 2, TRUE, 1 ), skor ),0)} -> 3 | I5: {=iferror(LET( kode, B5, ratio, XLOOKUP(kode, Audit!A:A, Audit!C:C), skor, IFS( ratio>90, 5, ratio>=85, 4, ratio>=80, 3, ratio>=75, 2, TRUE, 1 ), skor ),0)} -> 4 | J5: {=iferror(LET( kode, B5, ratio, XLOOKUP(kode, 'Mistery Shopper'!A:A, 'Mistery Shopper'!C:C), skor, IFS( ratio>90%, 5, ratio>=85%, 4, ratio>=80%, 3, ratio>=75%, 2, TRUE, 1 ), skor ),0)} -> 5 | K5: {=iferror(LET( kode, B5, actual, XLOOKUP(kode, Complain!A:A, Complain!E:E), target, XLOOKUP(kode, Complain!A:A, Complain!D:D), ratio, actual/target, skor, IFS( ratio>=0.16%, 1, ratio>=0.15%, 2, ratio>=0.125%, 3, ratio>=0.1%, 4, TRUE, 5 ), skor ),0)} -> 5 | L5: =LET( nilai, C5:K5, bobot, {0.4,0.1,0.05,0.05,0.05,0.05,0.15,0.05,0.1}, SUMPRODUCT(nilai,bobot) )/5 -> 0.82 | N5: Bagas | O5: =averageif(A:A,N5,L:L) -> 0.455
A6: Nadine | B6: Margonda | C6: {=iferror(LET(kode, B6, actual, XLOOKUP(kode, Sales!A:A, Sales!E:E),target, XLOOKUP(kode, Sales!A:A, Sales!D:D),ratio, actual/target,skor, IFS(ratio>1, 5,ratio>=0.975, 4,ratio>=0.95, 3,ratio>=0.9, 2,TRUE, 1),skor),0)} -> 4 | D6: {=iferror(LET( kode, B6, actual, XLOOKUP(kode, AVG!A:A, AVG!E:E), target, XLOOKUP(kode, AVG!A:A, AVG!D:D), ratio, actual/target, skor, IFS( ratio>1, 5, ratio>=0.975, 4, ratio>=0.95, 3, ratio>=0.9, 2, TRUE, 1 ), skor ),0)} -> 4 | E6: {=iferror(LET( kode, B6, large, XLOOKUP(kode, Large!A:A, Large!E:E), small, XLOOKUP(kode, Large!A:A, Large!D:D), ratio, large/(large+small), skor, IFS( ratio<0.45, 1, ratio<=0.5, 2, ratio<=0.55, 3, ratio<=0.6, 4, TRUE, 5 ), skor ),0)} -> 1 | F6: {=iferror(LET( kode, B6, oatmilk, XLOOKUP(kode, Oatside!A:A, Oatside!E:E), drink, XLOOKUP(kode, Oatside!A:A, Oatside!D:D), ratio, oatmilk/drink, skor, IFS( ratio>5%, 5, ratio>=4%, 4, ratio>=3%, 3, ratio>=2%, 2, TRUE, 1 ), skor ),0)} -> 5 | G6: {=iferror(LET( kode, B6, actual, XLOOKUP(kode, 'Snack Platter'!A:A, 'Snack Platter'!E:E), target, XLOOKUP(kode, 'Snack Platter'!A:A, 'Snack Platter'!D:D), ratio, actual/target, skor, IFS( ratio>10%, 5, ratio>=7.5%, 4, ratio>=5%, 3, ratio>=2.5%, 2, TRUE, 1 ), skor ),0)} -> 3 | H6: {=iferror(LET( kode, B6, actual, XLOOKUP(kode, 'Bundling Asik'!A:A, 'Bundling Asik'!E:E), target, XLOOKUP(kode, 'Bundling Asik'!A:A, 'Bundling Asik'!D:D), ratio, actual/target, skor, IFS( ratio>5%, 5, ratio>=4%, 4, ratio>=3%, 3, ratio>=2%, 2, TRUE, 1 ), skor ),0)} -> 5 | I6: {=iferror(LET( kode, B6, ratio, XLOOKUP(kode, Audit!A:A, Audit!C:C), skor, IFS( ratio>90, 5, ratio>=85, 4, ratio>=80, 3, ratio>=75, 2, TRUE, 1 ), skor ),0)} -> 3 | J6: {=iferror(LET( kode, B6, ratio, XLOOKUP(kode, 'Mistery Shopper'!A:A, 'Mistery Shopper'!C:C), skor, IFS( ratio>90%, 5, ratio>=85%, 4, ratio>=80%, 3, ratio>=75%, 2, TRUE, 1 ), skor ),0)} -> 5 | K6: {=iferror(LET( kode, B6, actual, XLOOKUP(kode, Complain!A:A, Complain!E:E), target, XLOOKUP(kode, Complain!A:A, Complain!D:D), ratio, actual/target, skor, IFS( ratio>=0.16%, 1, ratio>=0.15%, 2, ratio>=0.125%, 3, ratio>=0.1%, 4, TRUE, 5 ), skor ),0)} -> 5 | L6: =LET( nilai, C6:K6, bobot, {0.4,0.1,0.05,0.05,0.05,0.05,0.15,0.05,0.1}, SUMPRODUCT(nilai,bobot) )/5 -> 0.78 | N6: Ryan | O6: =averageif(A:A,N6,L:L) -> 0.43
